data/samples.json
{"schema_version":1,"generated_at_utc":"2026-09-22T03:03:43+00:00","export_hash":"sha256:019be056f64e3d3acb799966cb71f368845346f146a61c54ecca9bb0e4edf001","draws_per_model":2,"datasets":[{"dataset_id":"dow30_valday_flow_2026-06-23","task":"next_window_flow_dow30","summary":"FROZEN Dow 30 evaluation test bundle (v2 pipeline): next-window ADD-flow on 2026-06-23, all 30 constituents x 65 target windows (dw=300 s, 10:30-16:00 ET, strict 10:30 policy: inputs = window j-1 start at 10:30; first target 10:35). Built straight from the raw full-depth LOBSTER message streams via the audited order_flow_histogram_v1 flow engine (closed='left', absolute penny ticks). Immutable (SUCCESS + SHA256SUMS); inputs serve flow-window-sparse/v1 and dit-conditioning/v1. Built by studies/20260819_dow30_valday_evalset.","content_hash":"sha256:a68e77cbc31ec953927f838ce97c2a953a07422d110c112b18e70f03a9349422","board_run_id":"eval__20260914_dow30_v3_large__cfg6e4678be5d97__20260922T024737Z","reference":"input window's touch mid: round((max bid tick + min ask tick)/2)","views":{"overview":{"half_width_ticks":5000,"bin_ticks":25},"zoom":{"half_width_ticks":300,"bin_ticks":1}},"metrics":[{"metric_id":"sided_w1","primary_output":"sided_w1","unit":"ticks","direction":"lower_is_better"},{"metric_id":"norm_total_volume_error","primary_output":"ntve","unit":"fraction","direction":"lower_is_better"},{"metric_id":"log1p_flow_mse","primary_output":"log1p_flow_mse","unit":"log1p_shares_sq","direction":"lower_is_better"},{"metric_id":"full_field_ot","primary_output":"d_full","unit":"share_ticks","direction":"lower_is_better"},{"metric_id":"energy_score","primary_output":"energy_score","unit":"dimensionless","direction":"lower_is_better"},{"metric_id":"energy_score_l2","primary_output":"energy_score_l2","unit":"log1p_shares","direction":"lower_is_better"},{"metric_id":"total_volume_crps","primary_output":"total_volume_crps","unit":"log1p_shares","direction":"lower_is_better"},{"metric_id":"rank_calibration","primary_output":"rank_calibration","unit":"dimensionless","direction":"lower_is_better"}],"models":[{"model_id":"naive_flow__persistence","model_name":"naive_flow","family":"naive_flow","kind":"fit-at-predict","draws":[0],"prediction_id":"pred_3f5711fd3e21"},{"model_id":"skewnorm_mixture__base","model_name":"skewnorm_mixture","family":"skewnorm_mixture","kind":"fit-at-predict","draws":[0],"prediction_id":"pred_9f9a13158346"},{"model_id":"order_flow_dit__dit__dow30_v3__s42__cfg39412da9cf87","model_name":"order_flow_dit","family":"order_flow_dit","kind":"trained","draws":[0,1],"prediction_id":"pred_8cd1630bcd8f"},{"model_id":"order_flow_dit__dit__dow30_v3__s42__cfge223a305d4e5","model_name":"order_flow_dit","family":"order_flow_dit","kind":"trained","draws":[0,1],"prediction_id":"pred_ac87fbeababb"},{"model_id":"order_flow_dit_grpo__grpo__dow30_v2__s42__cfg394eed77cff6","model_name":"order_flow_dit_grpo","family":"order_flow_dit_grpo","kind":"trained","draws":[0,1],"prediction_id":"pred_4e86d9c705a3"},{"model_id":"order_flow_dit__dit__dow30_v2__s42__cfge91d5d1c3334","model_name":"order_flow_dit","family":"order_flow_dit","kind":"trained","draws":[0,1],"prediction_id":"pred_a636d4436656"},{"model_id":"naive_flow__profile__dow30_v2","model_name":"naive_flow","family":"naive_flow","kind":"fit-at-predict","draws":[0],"prediction_id":"pred_7383658c018a"},{"model_id":"order_flow_dit__dit__dow30_v1__s42__cfgc51a313e2251","model_name":"order_flow_dit","family":"order_flow_dit","kind":"trained","draws":[0,1],"prediction_id":"pred_4f8932ff0225"},{"model_id":"order_flow_dit__dit__dow30_v2__s42__cfg75175188ab25","model_name":"order_flow_dit","family":"order_flow_dit","kind":"trained","draws":[0,1],"prediction_id":"pred_763bcc1c8911"},{"model_id":"naive_flow__empirical__dow30_v2","model_name":"naive_flow_ensemble","family":"naive_flow_ensemble","kind":"fit-at-predict","draws":[0,1],"prediction_id":"pred_0e96531a4a1d"},{"model_id":"skewnorm_mixture__kmax2","model_name":"skewnorm_mixture","family":"skewnorm_mixture","kind":"fit-at-predict","draws":[0],"prediction_id":"pred_fff215b4d409"},{"model_id":"skewnorm_mixture__kmax1","model_name":"skewnorm_mixture","family":"skewnorm_mixture","kind":"fit-at-predict","draws":[0],"prediction_id":"pred_9f5c398f1dab"},{"model_id":"skewnorm__band","model_name":"skewnorm","family":"skewnorm","kind":"fit-at-predict","draws":[0],"prediction_id":"pred_8b0048dfdc8c"},{"model_id":"order_flow_maskdit_orders__mask__dow30_v2__s42__cfgb5542c355bdf","model_name":"order_flow_maskdit_orders","family":"order_flow_maskdit_orders","kind":"trained","draws":[0,1],"prediction_id":"pred_4ab09897dab9"},{"model_id":"order_flow_maskdit__mask__dow30_v2__s42__cfg6660a508eb19","model_name":"order_flow_maskdit","family":"order_flow_maskdit","kind":"trained","draws":[0,1],"prediction_id":"pred_a5d1e0a38b80"}],"windows":[{"sample_id":"s4be2827c6962eed0","symbol":"AAPL","trading_date":"2026-06-23","window_index":33,"ref_tick":29908,"tick_size":0.01,"input":{"mass":{"bid":1102584.0,"ask":608116.0},"overview":{"bid":{"sparse":true,"n":401,"i":[3,60,63,64,106,115,116,117,118,139,152,153,155,163,164,165,175,178,179,180,181,183,184,185,186,187,188,189,190,191,192,193,195,196,197,198,199,200,201],"v":[13.0,1.0,3.0,20.0,100.0,39900.0,280500.0,158200.0,600.0,1.0,40.0,360.0,1.0,15510.0,65520.0,14400.0,100.0,8.0,226.0,422.0,50.0,12.0,15.0,42.0,2160.0,22121.0,84080.0,70697.0,11880.0,671.0,2830.0,1641.0,472.0,4330.0,33242.0,89460.0,86994.0,108289.0,7648.0]},"ask":{"sparse":true,"n":401,"i":[198,199,200,201,202,203,204,205,206,207,208,209,210,211,212,213,215,216,218,219,220,221,223,233,234,235,236,245,246,247,263,282,283,284,285,292],"v":[845.0,45677.0,113299.0,22494.0,1715.0,2834.0,411.0,210.0,123.0,274.0,415.0,4090.0,25060.0,37350.0,37460.0,2810.0,15.0,10.0,2.0,146.0,254.0,58.0,113.0,10.0,6440.0,33440.0,12360.0,400.0,480.0,1000.0,120.0,1300.0,69901.0,161600.0,25300.0,100.0]}},"zoom":{"bid":{"sparse":true,"n":601,"i":[0,1,2,3,4,5,6,7,8,9,10,11,12,13,14,15,16,17,18,19,20,21,22,23,24,25,26,27,28,29,30,31,32,33,34,35,36,37,38,39,40,41,42,43,44,45,46,47,48,49,50,51,52,53,54,55,56,57,58,59,60,61,62,84,89,92,96,98,100,102,104,106,107,108,110,111,112,114,115,116,117,118,119,120,121,122,123,124,125,126,127,128,129,130,131,132,135,137,143,144,189,190,192,193,196,201,211,219,220,221,222,223,224,225,226,227,228,229,230,231,232,233,234,235,236,237,238,239,240,241,242,243,244,245,246,247,248,249,250,251,252,253,254,255,256,257,258,259,260,261,262,263,264,265,266,267,268,269,270,271,272,273,274,275,276,277,278,279,280,281,282,283,284,285,286,287,288,289,290,291,292,293,294,295,296,297,298,299,300,301,302,303,304,305,306,307,308,309,310,311,312,313,314,315,316,317,318,319,320,321,322,323,324,325,326,327,328,329,330,331],"v":[2800.0,6200.0,7800.0,6400.0,4680.0,2760.0,3160.0,4600.0,4080.0,3240.0,3360.0,4840.0,5040.0,4200.0,3200.0,2040.0,1480.0,1600.0,1320.0,1440.0,2040.0,2040.0,2360.0,1960.0,1440.0,1960.0,2200.0,2160.0,2040.0,1840.0,3080.0,6560.0,7040.0,5720.0,4040.0,2560.0,2760.0,3480.0,3120.0,2760.0,4000.0,4640.0,3240.0,3200.0,1777.0,920.0,760.0,240.0,40.0,560.0,680.0,1280.0,1320.0,960.0,1440.0,1640.0,1480.0,1040.0,480.0,440.0,720.0,240.0,160.0,16.0,100.0,355.0,100.0,100.0,100.0,100.0,16.0,63.0,100.0,132.0,31.0,100.0,63.0,32.0,100.0,130.0,200.0,215.0,400.0,116.0,200.0,416.0,100.0,216.0,200.0,215.0,200.0,115.0,300.0,16.0,80.0,15.0,100.0,200.0,100.0,100.0,160.0,160.0,141.0,10.0,1.0,50.0,160.0,640.0,960.0,240.0,840.0,480.0,960.0,1840.0,1000.0,360.0,840.0,720.0,840.0,1200.0,120.0,480.0,1080.0,850.0,480.0,2280.0,2290.0,1680.0,600.0,720.0,740.0,960.0,600.0,640.0,840.0,842.0,4040.0,7200.0,7680.0,7400.0,5220.0,1240.0,3000.0,3844.0,5009.0,5006.0,2817.0,2576.0,4469.0,4622.0,2475.0,1211.0,604.0,817.0,690.0,1456.0,2013.0,2328.0,2129.0,2604.0,10542.0,5702.0,4006.0,2805.0,3886.0,4757.0,3082.0,3427.0,3015.0,3866.0,3795.0,2620.0,3387.0,3696.0,3345.0,2519.0,3294.0,4019.0,2619.0,2563.0,4680.0,3218.0,1665.0,2089.0,2862.0,3051.0,5323.0,7411.0,
